-------------------------------------------------
|                  Events:                      |
-------------------------------------------------

at time 428: [job 0 arrived at CPU_queue]
at time 428: [job 0 entered CPU (burst time:638)]
at time 1065: [job 0 arrived at disk1_queue]
at time 1065: [job 0 entered disk1 (disk compute time:6193)]
at time 1131: [job 1 arrived at CPU_queue]
at time 1131: [job 1 entered CPU (burst time:496)]
at time 1626: [job 1 destroyed]
at time 2022: [job 2 arrived at CPU_queue]
at time 2022: [job 2 entered CPU (burst time:103)]
at time 2124: [job 2 arrived at disk2_queue]
at time 2124: [job 2 entered disk2 (disk compute time:13279)]
at time 2825: [job 3 arrived at CPU_queue]
at time 2825: [job 3 entered CPU (burst time:492)]
at time 3316: [job 3 arrived at disk1_queue]
at time 3475: [job 4 arrived at CPU_queue]
at time 3475: [job 4 entered CPU (burst time:305)]
at time 3779: [job 4 arrived at disk2_queue]
at time 4447: [job 5 arrived at CPU_queue]
at time 4447: [job 5 entered CPU (burst time:608)]
at time 4937: [job 6 arrived at CPU_queue]
at time 5054: [job 5 destroyed]
at time 5055: [job 6 entered CPU (burst time:266)]
at time 5164: [job 7 arrived at CPU_queue]
at time 5320: [job 6 arrived at disk1_queue]
at time 5321: [job 7 entered CPU (burst time:399)]
at time 5719: [job 7 arrived at disk2_queue]
at time 6140: [job 8 arrived at CPU_queue]
at time 6140: [job 8 entered CPU (burst time:934)]
at time 7073: [job 8 arrived at disk1_queue]
at time 7157: [job 9 arrived at CPU_queue]
at time 7157: [job 9 entered CPU (burst time:464)]
at time 7620: [job 9 destroyed]
at time 7621: [job 0 returned from disk 1 to CPU_queue]
at time 7621: [job 0 entered CPU (burst time:156)]
at time 7621: [job 3 entered disk1 (disk compute time:7216)]
at time 7776: [job 0 arrived at disk1_queue]
at time 7941: [job 10 arrived at CPU_queue]
at time 7941: [job 10 entered CPU (burst time:497)]
at time 8437: [job 10 arrived at disk2_queue]
at time 8572: [job 11 arrived at CPU_queue]
at time 8572: [job 11 entered CPU (burst time:315)]
at time 8882: [job 12 arrived at CPU_queue]
at time 8886: [job 11 destroyed]
at time 8887: [job 12 entered CPU (burst time:685)]
at time 10011: [job 13 arrived at CPU_queue]
at time 10011: [job 13 entered CPU (burst time:295)]
at time 10059: [job 14 arrived at CPU_queue]
at time 10305: [job 13 destroyed]
at time 10306: [job 14 entered CPU (burst time:997)]
at time 10763: [job 15 arrived at CPU_queue]
at time 10876: [job 16 arrived at CPU_queue]
at time 10935: [job 17 arrived at CPU_queue]
at time 11303: [job 15 entered CPU (burst time:766)]
at time 12069: [job 16 entered CPU (burst time:169)]
at time 12218: [job 18 arrived at CPU_queue]
at time 12238: [job 17 entered CPU (burst time:669)]
at time 12907: [job 18 entered CPU (burst time:711)]
at time 13247: [job 19 arrived at CPU_queue]
at time 13618: [job 19 entered CPU (burst time:269)]
at time 13886: [job 19 destroyed]
at time 14309: [job 20 arrived at CPU_queue]
at time 14309: [job 20 entered CPU (burst time:577)]
at time 14885: [job 20 destroyed]
at time 14886: [job 3 returned from disk 1 to CPU_queue]
at time 14886: [job 3 entered CPU (burst time:170)]
at time 14886: [job 6 entered disk1 (disk compute time:10483)]
at time 15055: [job 3 arrived at disk1_queue]
at time 15403: [job 2 returned from disk 2 to CPU_queue]
at time 15403: [job 2 entered CPU (burst time:105)]
at time 15403: [job 4 entered disk2 (disk compute time:14311)]
at time 15507: [job 2 arrived at disk2_queue]
at time 15709: [job 21 arrived at CPU_queue]
at time 15709: [job 21 entered CPU (burst time:559)]
at time 16922: [job 22 arrived at CPU_queue]
at time 16922: [job 22 entered CPU (burst time:72)]
at time 17184: [job 23 arrived at CPU_queue]
at time 17184: [job 23 entered CPU (burst time:833)]
at time 17793: [job 24 arrived at CPU_queue]
at time 18016: [job 23 destroyed]
at time 18017: [job 24 entered CPU (burst time:726)]
at time 19138: [job 25 arrived at CPU_queue]
at time 19138: [job 25 entered CPU (burst time:843)]
at time 20242: [job 26 arrived at CPU_queue]
at time 20242: [job 26 entered CPU (burst time:525)]
at time 20819: [job 27 arrived at CPU_queue]
at time 20819: [job 27 entered CPU (burst time:230)]
at time 21214: [job 28 arrived at CPU_queue]
at time 21214: [job 28 entered CPU (burst time:300)]
at time 22359: [job 29 arrived at CPU_queue]
at time 22359: [job 29 entered CPU (burst time:281)]
at time 22626: [job 30 arrived at CPU_queue]
at time 22640: [job 30 entered CPU (burst time:87)]
at time 23778: [job 31 arrived at CPU_queue]
at time 23778: [job 31 entered CPU (burst time:247)]
at time 24736: [job 32 arrived at CPU_queue]
at time 24736: [job 32 entered CPU (burst time:948)]
at time 25684: [job 6 returned from disk 1 to CPU_queue]
at time 25684: [job 6 entered CPU (burst time:894)]
at time 25684: [job 8 entered disk1 (disk compute time:4933)]
at time 26148: [job 33 arrived at CPU_queue]
at time 26577: [job 6 arrived at disk1_queue]
at time 26578: [job 33 entered CPU (burst time:74)]
at time 26918: [job 34 arrived at CPU_queue]
at time 26918: [job 34 entered CPU (burst time:402)]
at time 28256: [job 35 arrived at CPU_queue]
at time 28256: [job 35 entered CPU (burst time:463)]
at time 28317: [job 36 arrived at CPU_queue]
at time 28719: [job 36 entered CPU (burst time:40)]
at time 28758: [job 36 destroyed]
at time 29714: [job 4 returned from disk 2 to CPU_queue]
at time 29714: [job 4 entered CPU (burst time:670)]
at time 29714: [job 7 entered disk2 (disk compute time:11835)]
at time 29715: [job 37 arrived at CPU_queue]
at time 29937: [job 38 arrived at CPU_queue]
at time 30190: [job 39 arrived at CPU_queue]
at time 30383: [job 4 arrived at disk2_queue]
at time 30384: [job 37 entered CPU (burst time:670)]
at time 30920: [job 40 arrived at CPU_queue]
at time 31053: [job 37 destroyed]
at time 31054: [job 8 returned from disk 1 to CPU_queue]
at time 31054: [job 38 entered CPU (burst time:728)]
at time 31054: [job 0 entered disk1 (disk compute time:10304)]
at time 31781: [job 38 arrived at disk1_queue]
at time 31782: [job 39 entered CPU (burst time:966)]
at time 31988: [job 41 arrived at CPU_queue]
at time 32747: [job 39 destroyed]
at time 32748: [job 40 entered CPU (burst time:424)]
at time 33171: [job 40 destroyed]
at time 33172: [job 8 entered CPU (burst time:191)]
at time 33363: [job 41 entered CPU (burst time:67)]
at time 33429: [job 41 destroyed]
at time 33470: [job 42 arrived at CPU_queue]
at time 33470: [job 42 entered CPU (burst time:390)]
at time 33859: [job 42 destroyed]
at time 33954: [job 43 arrived at CPU_queue]
at time 33954: [job 43 entered CPU (burst time:810)]
at time 34923: [job 44 arrived at CPU_queue]
at time 34923: [job 44 entered CPU (burst time:385)]
at time 35495: [job 45 arrived at CPU_queue]
at time 35495: [job 45 entered CPU (burst time:703)]
at time 36118: [job 46 arrived at CPU_queue]
at time 36198: [job 46 entered CPU (burst time:184)]
at time 36381: [job 46 destroyed]
at time 36812: [job 47 arrived at CPU_queue]
at time 36812: [job 47 entered CPU (burst time:711)]
at time 37591: [job 48 arrived at CPU_queue]
at time 37591: [job 48 entered CPU (burst time:960)]
at time 38851: [job 49 arrived at CPU_queue]
at time 38851: [job 49 entered CPU (burst time:580)]
at time 39430: [job 49 destroyed]
at time 39786: [job 50 arrived at CPU_queue]
at time 39786: [job 50 entered CPU (burst time:556)]
at time 40341: [job 50 destroyed]
at time 41140: [job 51 arrived at CPU_queue]
at time 41140: [job 51 entered CPU (burst time:412)]
at time 41552: [job 0 returned from disk 1 to CPU_queue]
at time 41552: [job 7 returned from disk 2 to CPU_queue]
at time 41552: [job 0 entered CPU (burst time:114)]
at time 41552: [job 3 entered disk1 (disk compute time:11349)]
at time 41552: [job 10 entered disk2 (disk compute time:13432)]
at time 41665: [job 0 destroyed]
at time 41666: [job 7 entered CPU (burst time:640)]
at time 41820: [job 52 arrived at CPU_queue]
at time 42305: [job 7 destroyed]
at time 42306: [job 52 entered CPU (burst time:452)]
at time 42757: [job 52 destroyed]
at time 42758: [job 53 arrived at CPU_queue]
at time 42758: [job 53 entered CPU (burst time:785)]
at time 43542: [job 53 arrived at disk1_queue]
at time 43629: [job 54 arrived at CPU_queue]
at time 43629: [job 54 entered CPU (burst time:681)]
at time 44309: [job 54 arrived at disk2_queue]
at time 44708: [job 55 arrived at CPU_queue]
at time 44708: [job 55 entered CPU (burst time:925)]
at time 45460: [job 56 arrived at CPU_queue]
at time 45633: [job 56 entered CPU (burst time:161)]
at time 46887: [job 57 arrived at CPU_queue]
at time 46887: [job 57 entered CPU (burst time:16)]
at time 47650: [job 58 arrived at CPU_queue]
at time 47650: [job 58 entered CPU (burst time:760)]
at time 48928: [job 59 arrived at CPU_queue]
at time 48928: [job 59 entered CPU (burst time:175)]
at time 49005: [job 60 arrived at CPU_queue]
at time 49019: [job 61 arrived at CPU_queue]
at time 49103: [job 60 entered CPU (burst time:784)]
at time 49887: [job 61 entered CPU (burst time:102)]
at time 50437: [job 62 arrived at CPU_queue]
at time 50437: [job 62 entered CPU (burst time:73)]
at time 51550: [job 63 arrived at CPU_queue]
at time 51550: [job 63 entered CPU (burst time:749)]
at time 51906: [job 64 arrived at CPU_queue]
at time 52299: [job 64 entered CPU (burst time:414)]
at time 52402: [job 65 arrived at CPU_queue]
at time 52712: [job 64 destroyed]
at time 52713: [job 65 entered CPU (burst time:870)]
at time 53583: [job 3 returned from disk 1 to CPU_queue]
at time 53583: [job 3 entered CPU (burst time:806)]
at time 53583: [job 6 entered disk1 (disk compute time:5218)]
at time 53777: [job 66 arrived at CPU_queue]
at time 54388: [job 3 destroyed]
at time 54389: [job 66 entered CPU (burst time:131)]
at time 54519: [job 66 arrived at disk1_queue]
at time 54984: [job 10 returned from disk 2 to CPU_queue]
at time 54984: [job 10 entered CPU (burst time:395)]
at time 54984: [job 2 entered disk2 (disk compute time:6345)]
at time 55049: [job 67 arrived at CPU_queue]
at time 55378: [job 10 destroyed]
at time 55379: [job 67 entered CPU (burst time:26)]
at time 55404: [job 67 arrived at disk2_queue]
at time 56474: [job 68 arrived at CPU_queue]
at time 56474: [job 68 entered CPU (burst time:199)]
at time 56672: [job 68 destroyed]
at time 57840: [job 69 arrived at CPU_queue]
at time 57840: [job 69 entered CPU (burst time:642)]
at time 58116: [job 70 arrived at CPU_queue]
at time 58482: [job 70 entered CPU (burst time:822)]
at time 59304: [job 6 returned from disk 1 to CPU_queue]
at time 59304: [job 6 entered CPU (burst time:153)]
at time 59304: [job 38 entered disk1 (disk compute time:14676)]
at time 59371: [job 71 arrived at CPU_queue]
at time 59456: [job 6 destroyed]
at time 59457: [job 71 entered CPU (burst time:878)]
at time 60334: [job 71 arrived at disk1_queue]
at time 60785: [job 72 arrived at CPU_queue]
at time 60785: [job 72 entered CPU (burst time:261)]
at time 61329: [job 2 returned from disk 2 to CPU_queue]
at time 61329: [job 2 entered CPU (burst time:350)]
at time 61329: [job 4 entered disk2 (disk compute time:13603)]
at time 61678: [job 2 destroyed]
at time 62257: [job 73 arrived at CPU_queue]
at time 62257: [job 73 entered CPU (burst time:174)]
at time 62430: [job 73 arrived at disk2_queue]
at time 62556: [job 74 arrived at CPU_queue]
at time 62556: [job 74 entered CPU (burst time:695)]
at time 63250: [job 74 destroyed]
at time 63512: [job 75 arrived at CPU_queue]
at time 63512: [job 75 entered CPU (burst time:177)]
at time 63990: [job 76 arrived at CPU_queue]
at time 63990: [job 76 entered CPU (burst time:965)]
at time 64562: [job 77 arrived at CPU_queue]
at time 64955: [job 77 entered CPU (burst time:403)]
at time 65029: [job 78 arrived at CPU_queue]
at time 65358: [job 78 entered CPU (burst time:601)]
at time 65948: [job 79 arrived at CPU_queue]
at time 65959: [job 79 entered CPU (burst time:795)]
at time 66029: [job 80 arrived at CPU_queue]
at time 66301: [job 81 arrived at CPU_queue]
at time 66754: [job 80 entered CPU (burst time:325)]
at time 66857: [job 82 arrived at CPU_queue]
at time 67079: [job 81 entered CPU (burst time:180)]
at time 67107: [job 83 arrived at CPU_queue]
at time 67259: [job 82 entered CPU (burst time:401)]
at time 67660: [job 83 entered CPU (burst time:225)]
at time 68567: [job 84 arrived at CPU_queue]
at time 68567: [job 84 entered CPU (burst time:383)]
at time 69567: [job 85 arrived at CPU_queue]
at time 69567: [job 85 entered CPU (burst time:227)]
at time 70106: [job 86 arrived at CPU_queue]
at time 70106: [job 86 entered CPU (burst time:586)]
at time 70691: [job 86 destroyed]
at time 71473: [job 87 arrived at CPU_queue]
at time 71473: [job 87 entered CPU (burst time:555)]
at time 72027: [job 87 destroyed]
at time 72629: [job 88 arrived at CPU_queue]
at time 72629: [job 88 entered CPU (burst time:20)]
at time 73349: [job 89 arrived at CPU_queue]
at time 73349: [job 89 entered CPU (burst time:163)]
at time 73511: [job 89 destroyed]
at time 73980: [job 38 returned from disk 1 to CPU_queue]
at time 73980: [job 38 entered CPU (burst time:547)]
at time 73980: [job 53 entered disk1 (disk compute time:3502)]
at time 74325: [job 90 arrived at CPU_queue]
at time 74526: [job 38 destroyed]
at time 74527: [job 90 entered CPU (burst time:932)]
at time 75250: [job 91 arrived at CPU_queue]
at time 75458: [job 90 arrived at disk1_queue]
at time 75459: [job 4 returned from disk 2 to CPU_queue]
at time 75459: [job 91 entered CPU (burst time:936)]
at time 75459: [job 54 entered disk2 (disk compute time:5580)]
at time 76394: [job 91 destroyed]
at time 76395: [job 4 entered CPU (burst time:715)]
at time 76508: [job 92 arrived at CPU_queue]
at time 77109: [job 4 arrived at disk2_queue]
at time 77110: [job 92 entered CPU (burst time:703)]
at time 77626: [job 93 arrived at CPU_queue]
at time 77813: [job 53 returned from disk 1 to CPU_queue]
at time 77813: [job 93 entered CPU (burst time:80)]
at time 77813: [job 66 entered disk1 (disk compute time:10879)]
at time 77892: [job 93 arrived at disk1_queue]
at time 77893: [job 53 entered CPU (burst time:47)]
at time 78491: [job 94 arrived at CPU_queue]
at time 78491: [job 94 entered CPU (burst time:472)]
at time 78586: [job 95 arrived at CPU_queue]
at time 78937: [job 96 arrived at CPU_queue]
at time 78963: [job 95 entered CPU (burst time:612)]
at time 79233: [job 97 arrived at CPU_queue]
at time 79575: [job 96 entered CPU (burst time:286)]
at time 79861: [job 97 entered CPU (burst time:177)]
at time 80007: [job 98 arrived at CPU_queue]
at time 80038: [job 98 entered CPU (burst time:472)]
at time 80528: [job 99 arrived at CPU_queue]
at time 80528: [job 99 entered CPU (burst time:939)]
at time 81467: [job 54 returned from disk 2 to CPU_queue]
at time 81467: [job 54 entered CPU (burst time:474)]
at time 81467: [job 67 entered disk2 (disk compute time:15000)]
at time 81940: [job 54 arrived at disk2_queue]
at time 81990: [job 100 arrived at CPU_queue]
at time 81990: [job 100 entered CPU (burst time:980)]
at time 82194: [job 101 arrived at CPU_queue]
at time 82762: [job 102 arrived at CPU_queue]
at time 82970: [job 101 entered CPU (burst time:953)]
at time 83461: [job 103 arrived at CPU_queue]
at time 83802: [job 104 arrived at CPU_queue]
at time 83923: [job 102 entered CPU (burst time:218)]
at time 84140: [job 102 destroyed]
at time 84141: [job 103 entered CPU (burst time:657)]
at time 84251: [job 105 arrived at CPU_queue]
at time 84709: [job 106 arrived at CPU_queue]
at time 84798: [job 104 entered CPU (burst time:399)]
at time 85196: [job 104 destroyed]
at time 85197: [job 105 entered CPU (burst time:623)]
at time 85820: [job 106 entered CPU (burst time:262)]
at time 85967: [job 107 arrived at CPU_queue]
at time 86082: [job 107 entered CPU (burst time:498)]
at time 87209: [job 108 arrived at CPU_queue]
at time 87209: [job 108 entered CPU (burst time:132)]
at time 87420: [job 109 arrived at CPU_queue]
at time 87420: [job 109 entered CPU (burst time:298)]
at time 87972: [job 110 arrived at CPU_queue]
at time 87972: [job 110 entered CPU (burst time:223)]
at time 88692: [job 66 returned from disk 1 to CPU_queue]
at time 88692: [job 66 entered CPU (burst time:763)]
at time 88692: [job 71 entered disk1 (disk compute time:8648)]
at time 88934: [job 111 arrived at CPU_queue]
at time 89454: [job 66 arrived at disk1_queue]
at time 89455: [job 111 entered CPU (burst time:473)]
at time 89825: [job 112 arrived at CPU_queue]
at time 89927: [job 111 destroyed]
at time 89928: [job 112 entered CPU (burst time:175)]
at time 90323: [job 113 arrived at CPU_queue]
at time 90323: [job 113 entered CPU (burst time:956)]
at time 90607: [job 114 arrived at CPU_queue]
at time 91279: [job 114 entered CPU (burst time:184)]
at time 92094: [job 115 arrived at CPU_queue]
at time 92094: [job 115 entered CPU (burst time:764)]
at time 92274: [job 116 arrived at CPU_queue]
at time 92857: [job 115 destroyed]
at time 92858: [job 116 entered CPU (burst time:289)]
at time 92928: [job 117 arrived at CPU_queue]
at time 93147: [job 117 entered CPU (burst time:779)]
at time 93718: [job 118 arrived at CPU_queue]
at time 93926: [job 118 entered CPU (burst time:832)]
at time 94922: [job 119 arrived at CPU_queue]
at time 94922: [job 119 entered CPU (burst time:97)]
at time 94971: [job 120 arrived at CPU_queue]
at time 95019: [job 120 entered CPU (burst time:91)]
at time 95678: [job 121 arrived at CPU_queue]
at time 95678: [job 121 entered CPU (burst time:296)]
at time 96467: [job 67 returned from disk 2 to CPU_queue]
at time 96467: [job 67 entered CPU (burst time:231)]
at time 96467: [job 73 entered disk2 (disk compute time:5575)]
at time 96697: [job 67 arrived at disk2_queue]
at time 96900: [job 122 arrived at CPU_queue]
at time 96900: [job 122 entered CPU (burst time:226)]
at time 97039: [job 123 arrived at CPU_queue]
at time 97126: [job 123 entered CPU (burst time:896)]
at time 97800: [job 124 arrived at CPU_queue]
at time 98022: [job 71 returned from disk 1 to CPU_queue]
at time 98022: [job 124 entered CPU (burst time:828)]
at time 98022: [job 90 entered disk1 (disk compute time:13344)]
at time 98506: [job 125 arrived at CPU_queue]
at time 98849: [job 126 arrived at CPU_queue]
at time 98849: [job 124 arrived at disk1_queue]
at time 98850: [job 71 entered CPU (burst time:758)]
at time 99608: [job 125 entered CPU (burst time:26)]
at time 99634: [job 126 entered CPU (burst time:398)]
at time 99642: [job 127 arrived at CPU_queue]





-------------------------------------------------
|                  Statistics:                  |
-------------------------------------------------

Stats for CPU:

averageQueueSize: 1.056900
utilization: 0.687770
maxResponseTime: 39273
averageResponseTime: 1434.587156
throughput: 0.001090
--------------------

Stats for disk1:

averageQueueSize: 3.741840
utilization: 0.989360
maxResponseTime: 42199
averageResponseTime: 28712.090909
throughput: 0.000110
--------------------

Stats for disk2:

averageQueueSize: 3.725410
utilization: 0.978770
maxResponseTime: 46547
averageResponseTime: 36339.125000
throughput: 0.000080
--------------------

